2020-09-19 10:58:25.574624
Traceback (most recent call last):
  File "03-traceback_example.py", line 5, in <module>
    raise Exception('This is the error message.')
Exception: This is the error message.
